[2020-04-23 16:19:13,712] ERROR in app: Exception on /trainSet/upload [POST]
Traceback (most recent call last):
  File "D:\Anaconda3\envs\vision_tf2\lib\site-packages\flask\app.py", line 2446, in wsgi_app
    response = self.full_dispatch_request()
  File "D:\Anaconda3\envs\vision_tf2\lib\site-packages\flask\app.py", line 1951, in full_dispatch_request
    rv = self.handle_user_exception(e)
  File "D:\Anaconda3\envs\vision_tf2\lib\site-packages\flask\app.py", line 1820, in handle_user_exception
    reraise(exc_type, exc_value, tb)
  File "D:\Anaconda3\envs\vision_tf2\lib\site-packages\flask\_compat.py", line 39, in reraise
    raise value
  File "D:\Anaconda3\envs\vision_tf2\lib\site-packages\flask\app.py", line 1949, in full_dispatch_request
    rv = self.dispatch_request()
  File "D:\Anaconda3\envs\vision_tf2\lib\site-packages\flask\app.py", line 1935, in dispatch_request
    return self.view_functions[rule.endpoint](**req.view_args)
  File "E:\스마트제조\sf_trains\sf_edge\edge_server\app\main\index.py", line 53, in trainSetUpload
    importlib.reload(temp)
UnboundLocalError: local variable 'temp' referenced before assignment
[2020-04-23 16:21:19,850] ERROR in app: Exception on /trainSet/upload [POST]
Traceback (most recent call last):
  File "D:\Anaconda3\envs\vision_tf2\lib\site-packages\flask\app.py", line 2446, in wsgi_app
    response = self.full_dispatch_request()
  File "D:\Anaconda3\envs\vision_tf2\lib\site-packages\flask\app.py", line 1951, in full_dispatch_request
    rv = self.handle_user_exception(e)
  File "D:\Anaconda3\envs\vision_tf2\lib\site-packages\flask\app.py", line 1820, in handle_user_exception
    reraise(exc_type, exc_value, tb)
  File "D:\Anaconda3\envs\vision_tf2\lib\site-packages\flask\_compat.py", line 39, in reraise
    raise value
  File "D:\Anaconda3\envs\vision_tf2\lib\site-packages\flask\app.py", line 1949, in full_dispatch_request
    rv = self.dispatch_request()
  File "D:\Anaconda3\envs\vision_tf2\lib\site-packages\flask\app.py", line 1935, in dispatch_request
    return self.view_functions[rule.endpoint](**req.view_args)
  File "E:\스마트제조\sf_trains\sf_edge\edge_server\app\main\index.py", line 53, in trainSetUpload
    importlib.reload(upFile)
UnboundLocalError: local variable 'temp' referenced before assignment
[2020-04-23 16:22:01,489] ERROR in app: Exception on /trainSet/upload [POST]
Traceback (most recent call last):
  File "D:\Anaconda3\envs\vision_tf2\lib\site-packages\flask\app.py", line 2446, in wsgi_app
    response = self.full_dispatch_request()
  File "D:\Anaconda3\envs\vision_tf2\lib\site-packages\flask\app.py", line 1951, in full_dispatch_request
    rv = self.handle_user_exception(e)
  File "D:\Anaconda3\envs\vision_tf2\lib\site-packages\flask\app.py", line 1820, in handle_user_exception
    reraise(exc_type, exc_value, tb)
  File "D:\Anaconda3\envs\vision_tf2\lib\site-packages\flask\_compat.py", line 39, in reraise
    raise value
  File "D:\Anaconda3\envs\vision_tf2\lib\site-packages\flask\app.py", line 1949, in full_dispatch_request
    rv = self.dispatch_request()
  File "D:\Anaconda3\envs\vision_tf2\lib\site-packages\flask\app.py", line 1935, in dispatch_request
    return self.view_functions[rule.endpoint](**req.view_args)
  File "E:\스마트제조\sf_trains\sf_edge\edge_server\app\main\index.py", line 53, in trainSetUpload
    importlib.reload(upFile)
UnboundLocalError: local variable 'upFile' referenced before assignment
[2020-04-23 16:32:51,278] ERROR in app: Exception on /trainSet/upload [POST]
Traceback (most recent call last):
  File "D:\Anaconda3\envs\vision_tf2\lib\site-packages\flask\app.py", line 2446, in wsgi_app
    response = self.full_dispatch_request()
  File "D:\Anaconda3\envs\vision_tf2\lib\site-packages\flask\app.py", line 1951, in full_dispatch_request
    rv = self.handle_user_exception(e)
  File "D:\Anaconda3\envs\vision_tf2\lib\site-packages\flask\app.py", line 1820, in handle_user_exception
    reraise(exc_type, exc_value, tb)
  File "D:\Anaconda3\envs\vision_tf2\lib\site-packages\flask\_compat.py", line 39, in reraise
    raise value
  File "D:\Anaconda3\envs\vision_tf2\lib\site-packages\flask\app.py", line 1949, in full_dispatch_request
    rv = self.dispatch_request()
  File "D:\Anaconda3\envs\vision_tf2\lib\site-packages\flask\app.py", line 1935, in dispatch_request
    return self.view_functions[rule.endpoint](**req.view_args)
  File "E:\스마트제조\sf_trains\sf_edge\edge_server\app\main\index.py", line 50, in trainSetUpload
    f.save('upload/' + secure_filename(f.filename))
  File "D:\Anaconda3\envs\vision_tf2\lib\site-packages\werkzeug\datastructures.py", line 2800, in save
    dst = open(dst, "wb")
FileNotFoundError: [Errno 2] No such file or directory: 'upload/train.py'
[2020-04-23 16:33:28,344] ERROR in app: Exception on /trainSet/upload [POST]
Traceback (most recent call last):
  File "D:\Anaconda3\envs\vision_tf2\lib\site-packages\flask\app.py", line 2446, in wsgi_app
    response = self.full_dispatch_request()
  File "D:\Anaconda3\envs\vision_tf2\lib\site-packages\flask\app.py", line 1951, in full_dispatch_request
    rv = self.handle_user_exception(e)
  File "D:\Anaconda3\envs\vision_tf2\lib\site-packages\flask\app.py", line 1820, in handle_user_exception
    reraise(exc_type, exc_value, tb)
  File "D:\Anaconda3\envs\vision_tf2\lib\site-packages\flask\_compat.py", line 39, in reraise
    raise value
  File "D:\Anaconda3\envs\vision_tf2\lib\site-packages\flask\app.py", line 1949, in full_dispatch_request
    rv = self.dispatch_request()
  File "D:\Anaconda3\envs\vision_tf2\lib\site-packages\flask\app.py", line 1935, in dispatch_request
    return self.view_functions[rule.endpoint](**req.view_args)
  File "E:\스마트제조\sf_trains\sf_edge\edge_server\app\main\index.py", line 53, in trainSetUpload
    import runpy.train as pyfile
ModuleNotFoundError: No module named 'runpy.train'; 'runpy' is not a package
[2020-04-23 16:34:38,995] ERROR in app: Exception on /trainSet/upload [POST]
Traceback (most recent call last):
  File "D:\Anaconda3\envs\vision_tf2\lib\site-packages\flask\app.py", line 2446, in wsgi_app
    response = self.full_dispatch_request()
  File "D:\Anaconda3\envs\vision_tf2\lib\site-packages\flask\app.py", line 1951, in full_dispatch_request
    rv = self.handle_user_exception(e)
  File "D:\Anaconda3\envs\vision_tf2\lib\site-packages\flask\app.py", line 1820, in handle_user_exception
    reraise(exc_type, exc_value, tb)
  File "D:\Anaconda3\envs\vision_tf2\lib\site-packages\flask\_compat.py", line 39, in reraise
    raise value
  File "D:\Anaconda3\envs\vision_tf2\lib\site-packages\flask\app.py", line 1949, in full_dispatch_request
    rv = self.dispatch_request()
  File "D:\Anaconda3\envs\vision_tf2\lib\site-packages\flask\app.py", line 1935, in dispatch_request
    return self.view_functions[rule.endpoint](**req.view_args)
  File "E:\스마트제조\sf_trains\sf_edge\edge_server\app\main\index.py", line 51, in trainSetUpload
    f.save('runpy/' + secure_filename(f.filename))
  File "D:\Anaconda3\envs\vision_tf2\lib\site-packages\werkzeug\datastructures.py", line 2800, in save
    dst = open(dst, "wb")
FileNotFoundError: [Errno 2] No such file or directory: 'runpy/train.py'
